<mujoco model="inverted_pendulum">
  <option gravity="0 0 -9.81" timestep="0.01"/>
  <compiler inertiafromgeom="true"/>

  <worldbody>
    <geom name="ground" type="plane" size="10 10 0.1" pos="0 0 0" rgba="0.8 0.9 0.8 1"/>
    <body name="cart" pos="0 0 0.05">
      <geom name="cart_geom" type="box" size="0.1 0.1 0.05" rgba="0.3 0.3 0.7 1"/>
      <body name="pole" pos="0 0 0.05">
        <joint name="hinge" type="hinge" axis="0 1 0"/>
        <geom name="pole_geom" type="capsule" fromto="0 0 0 0 0 0.6" size="0.04" rgba="0 0.7 0.7 1"/>
      </body>
    </body>
  </worldbody>

</mujoco>
